2024-12-22 03:33:20,760 - main - ERROR - Validation error: [{'type': 'enum', 'loc': ('body', 'コメント受信設定', 'ニコニコ生放送', 'コメント受信'), 'msg': "Input should be 'ON' or 'OFF'", 'input': {'_candidate': ['ON', 'OFF'], '_value': 'OFF'}, 'ctx': {'expected': "'ON' or 'OFF'"}}, {'type': 'enum', 'loc': ('body', 'GPT設定', 'GPT起動状況'), 'msg': "Input should be 'ON' or 'OFF'", 'input': {'_candidate': ['ON', 'OFF'], '_value': 'OFF'}, 'ctx': {'expected': "'ON' or 'OFF'"}}]
2024-12-22 03:36:38,301 - main - ERROR - Validation error: [{'type': 'enum', 'loc': ('body', 'コメント受信設定', 'ニコニコ生放送', 'コメント受信'), 'msg': "Input should be 'ON' or 'OFF'", 'input': {'_candidate': ['ON', 'OFF'], '_value': 'OFF'}, 'ctx': {'expected': "'ON' or 'OFF'"}}, {'type': 'enum', 'loc': ('body', 'GPT設定', 'GPT起動状況'), 'msg': "Input should be 'ON' or 'OFF'", 'input': {'_candidate': ['ON', 'OFF'], '_value': 'OFF'}, 'ctx': {'expected': "'ON' or 'OFF'"}}]
2024-12-22 04:22:56,017 - main - ERROR - Unhandled exception: Expecting value: line 1 column 1 (char 0)
2024-12-22 04:24:33,076 - main - ERROR - Unhandled exception: Expecting value: line 1 column 1 (char 0)
2025-01-05 01:56:45,411 - main - ERROR - Unhandled exception: 'NoneType' object has no attribute 'Length'
2025-01-05 02:00:12,091 - main - ERROR - Unhandled exception: 'int' object is not iterable
2025-01-07 23:19:20,134 - main - ERROR - Unhandled exception: HTTPConnectionPool(host='localhost', port=50021): Max retries exceeded with url: /speakers (Caused by NewConnectionError('<urllib3.connection.HTTPConnection object at 0x000002C2FFB39790>: Failed to establish a new connection: [WinError 10061] 対象のコンピューターによって拒否されたため、接続できませんでした。'))
2025-01-08 00:07:26,868 - main - ERROR - Unhandled exception: asyncio.run() cannot be called from a running event loop
2025-01-08 00:07:27,179 - main - ERROR - Unhandled exception: asyncio.run() cannot be called from a running event loop
2025-01-08 00:07:31,014 - main - ERROR - Unhandled exception: asyncio.run() cannot be called from a running event loop
2025-01-08 00:07:31,323 - main - ERROR - Unhandled exception: asyncio.run() cannot be called from a running event loop
2025-01-08 00:07:31,329 - main - ERROR - Unhandled exception: asyncio.run() cannot be called from a running event loop
2025-01-08 00:07:31,417 - main - ERROR - Unhandled exception: asyncio.run() cannot be called from a running event loop
2025-01-08 00:07:31,421 - main - ERROR - Unhandled exception: asyncio.run() cannot be called from a running event loop
2025-01-08 00:07:31,427 - main - ERROR - Unhandled exception: asyncio.run() cannot be called from a running event loop
2025-01-08 00:07:31,432 - main - ERROR - Unhandled exception: asyncio.run() cannot be called from a running event loop
2025-01-08 00:07:31,643 - main - ERROR - Unhandled exception: asyncio.run() cannot be called from a running event loop
2025-01-08 00:07:31,649 - main - ERROR - Unhandled exception: asyncio.run() cannot be called from a running event loop
2025-01-08 00:07:31,743 - main - ERROR - Unhandled exception: asyncio.run() cannot be called from a running event loop
2025-01-08 00:07:31,748 - main - ERROR - Unhandled exception: asyncio.run() cannot be called from a running event loop
2025-01-08 00:07:31,753 - main - ERROR - Unhandled exception: asyncio.run() cannot be called from a running event loop
2025-01-08 00:07:31,757 - main - ERROR - Unhandled exception: asyncio.run() cannot be called from a running event loop
2025-01-08 00:07:31,958 - main - ERROR - Unhandled exception: asyncio.run() cannot be called from a running event loop
2025-01-08 00:07:31,964 - main - ERROR - Unhandled exception: asyncio.run() cannot be called from a running event loop
2025-01-08 00:07:32,071 - main - ERROR - Unhandled exception: asyncio.run() cannot be called from a running event loop
2025-01-08 00:07:32,076 - main - ERROR - Unhandled exception: asyncio.run() cannot be called from a running event loop
2025-01-08 00:07:32,082 - main - ERROR - Unhandled exception: asyncio.run() cannot be called from a running event loop
2025-01-08 00:07:32,088 - main - ERROR - Unhandled exception: asyncio.run() cannot be called from a running event loop
2025-01-08 00:07:32,271 - main - ERROR - Unhandled exception: asyncio.run() cannot be called from a running event loop
2025-01-08 00:07:32,276 - main - ERROR - Unhandled exception: asyncio.run() cannot be called from a running event loop
2025-01-08 00:07:32,396 - main - ERROR - Unhandled exception: asyncio.run() cannot be called from a running event loop
2025-01-08 00:07:32,402 - main - ERROR - Unhandled exception: asyncio.run() cannot be called from a running event loop
2025-01-08 00:07:32,407 - main - ERROR - Unhandled exception: asyncio.run() cannot be called from a running event loop
2025-01-08 00:07:32,413 - main - ERROR - Unhandled exception: asyncio.run() cannot be called from a running event loop
2025-01-08 00:07:32,598 - main - ERROR - Unhandled exception: asyncio.run() cannot be called from a running event loop
2025-01-08 00:07:32,603 - main - ERROR - Unhandled exception: asyncio.run() cannot be called from a running event loop
2025-01-08 00:07:32,722 - main - ERROR - Unhandled exception: asyncio.run() cannot be called from a running event loop
2025-01-08 00:07:32,729 - main - ERROR - Unhandled exception: asyncio.run() cannot be called from a running event loop
2025-01-08 00:07:32,735 - main - ERROR - Unhandled exception: asyncio.run() cannot be called from a running event loop
2025-01-08 00:07:32,740 - main - ERROR - Unhandled exception: asyncio.run() cannot be called from a running event loop
2025-01-08 00:07:32,924 - main - ERROR - Unhandled exception: asyncio.run() cannot be called from a running event loop
2025-01-08 00:07:32,930 - main - ERROR - Unhandled exception: asyncio.run() cannot be called from a running event loop
2025-01-08 00:07:33,050 - main - ERROR - Unhandled exception: asyncio.run() cannot be called from a running event loop
2025-01-08 00:07:33,055 - main - ERROR - Unhandled exception: asyncio.run() cannot be called from a running event loop
2025-01-08 00:07:33,059 - main - ERROR - Unhandled exception: asyncio.run() cannot be called from a running event loop
2025-01-08 00:07:33,066 - main - ERROR - Unhandled exception: asyncio.run() cannot be called from a running event loop
2025-01-08 00:07:33,251 - main - ERROR - Unhandled exception: asyncio.run() cannot be called from a running event loop
2025-01-08 00:07:33,256 - main - ERROR - Unhandled exception: asyncio.run() cannot be called from a running event loop
2025-01-08 00:07:33,375 - main - ERROR - Unhandled exception: asyncio.run() cannot be called from a running event loop
2025-01-08 00:07:33,382 - main - ERROR - Unhandled exception: asyncio.run() cannot be called from a running event loop
2025-01-08 00:07:33,386 - main - ERROR - Unhandled exception: asyncio.run() cannot be called from a running event loop
2025-01-08 00:07:33,391 - main - ERROR - Unhandled exception: asyncio.run() cannot be called from a running event loop
2025-01-08 00:07:33,578 - main - ERROR - Unhandled exception: asyncio.run() cannot be called from a running event loop
2025-01-08 00:07:33,585 - main - ERROR - Unhandled exception: asyncio.run() cannot be called from a running event loop
2025-01-08 00:07:33,701 - main - ERROR - Unhandled exception: asyncio.run() cannot be called from a running event loop
2025-01-08 00:07:33,706 - main - ERROR - Unhandled exception: asyncio.run() cannot be called from a running event loop
2025-01-08 00:07:33,711 - main - ERROR - Unhandled exception: asyncio.run() cannot be called from a running event loop
2025-01-08 00:07:33,716 - main - ERROR - Unhandled exception: asyncio.run() cannot be called from a running event loop
2025-01-08 00:07:33,902 - main - ERROR - Unhandled exception: asyncio.run() cannot be called from a running event loop
2025-01-08 00:07:33,907 - main - ERROR - Unhandled exception: asyncio.run() cannot be called from a running event loop
2025-01-08 00:07:34,026 - main - ERROR - Unhandled exception: asyncio.run() cannot be called from a running event loop
2025-01-08 00:07:34,032 - main - ERROR - Unhandled exception: asyncio.run() cannot be called from a running event loop
2025-01-08 00:07:34,037 - main - ERROR - Unhandled exception: asyncio.run() cannot be called from a running event loop
2025-01-08 00:07:34,041 - main - ERROR - Unhandled exception: asyncio.run() cannot be called from a running event loop
2025-01-08 00:07:34,228 - main - ERROR - Unhandled exception: asyncio.run() cannot be called from a running event loop
2025-01-08 00:07:34,233 - main - ERROR - Unhandled exception: asyncio.run() cannot be called from a running event loop
2025-01-08 00:07:34,352 - main - ERROR - Unhandled exception: asyncio.run() cannot be called from a running event loop
2025-01-08 00:07:34,356 - main - ERROR - Unhandled exception: asyncio.run() cannot be called from a running event loop
2025-01-08 00:07:34,362 - main - ERROR - Unhandled exception: asyncio.run() cannot be called from a running event loop
2025-01-08 00:07:34,368 - main - ERROR - Unhandled exception: asyncio.run() cannot be called from a running event loop
2025-01-08 00:07:34,553 - main - ERROR - Unhandled exception: asyncio.run() cannot be called from a running event loop
2025-01-08 00:07:34,557 - main - ERROR - Unhandled exception: asyncio.run() cannot be called from a running event loop
2025-01-08 00:07:34,679 - main - ERROR - Unhandled exception: asyncio.run() cannot be called from a running event loop
2025-01-08 00:07:34,683 - main - ERROR - Unhandled exception: asyncio.run() cannot be called from a running event loop
2025-01-08 00:07:34,688 - main - ERROR - Unhandled exception: asyncio.run() cannot be called from a running event loop
2025-01-08 00:07:34,693 - main - ERROR - Unhandled exception: asyncio.run() cannot be called from a running event loop
2025-01-08 00:07:34,865 - main - ERROR - Unhandled exception: asyncio.run() cannot be called from a running event loop
2025-01-08 00:07:34,870 - main - ERROR - Unhandled exception: asyncio.run() cannot be called from a running event loop
2025-01-08 00:07:35,005 - main - ERROR - Unhandled exception: asyncio.run() cannot be called from a running event loop
2025-01-08 00:07:35,010 - main - ERROR - Unhandled exception: asyncio.run() cannot be called from a running event loop
2025-01-08 00:07:35,016 - main - ERROR - Unhandled exception: asyncio.run() cannot be called from a running event loop
2025-01-08 00:07:35,021 - main - ERROR - Unhandled exception: asyncio.run() cannot be called from a running event loop
2025-01-08 00:07:35,176 - main - ERROR - Unhandled exception: asyncio.run() cannot be called from a running event loop
2025-01-08 00:07:35,181 - main - ERROR - Unhandled exception: asyncio.run() cannot be called from a running event loop
2025-01-08 00:07:35,332 - main - ERROR - Unhandled exception: asyncio.run() cannot be called from a running event loop
2025-01-08 00:07:35,337 - main - ERROR - Unhandled exception: asyncio.run() cannot be called from a running event loop
2025-01-08 00:07:35,342 - main - ERROR - Unhandled exception: asyncio.run() cannot be called from a running event loop
2025-01-08 00:07:35,348 - main - ERROR - Unhandled exception: asyncio.run() cannot be called from a running event loop
2025-01-08 00:07:35,502 - main - ERROR - Unhandled exception: asyncio.run() cannot be called from a running event loop
2025-01-08 00:07:35,507 - main - ERROR - Unhandled exception: asyncio.run() cannot be called from a running event loop
2025-01-08 00:07:35,656 - main - ERROR - Unhandled exception: asyncio.run() cannot be called from a running event loop
2025-01-08 00:07:35,662 - main - ERROR - Unhandled exception: asyncio.run() cannot be called from a running event loop
2025-01-08 00:07:35,667 - main - ERROR - Unhandled exception: asyncio.run() cannot be called from a running event loop
2025-01-08 00:07:35,672 - main - ERROR - Unhandled exception: asyncio.run() cannot be called from a running event loop
2025-01-08 00:07:35,828 - main - ERROR - Unhandled exception: asyncio.run() cannot be called from a running event loop
2025-01-08 00:07:35,832 - main - ERROR - Unhandled exception: asyncio.run() cannot be called from a running event loop
2025-01-08 00:07:35,985 - main - ERROR - Unhandled exception: asyncio.run() cannot be called from a running event loop
2025-01-08 00:07:35,991 - main - ERROR - Unhandled exception: asyncio.run() cannot be called from a running event loop
2025-01-08 00:07:35,997 - main - ERROR - Unhandled exception: asyncio.run() cannot be called from a running event loop
2025-01-08 00:07:36,003 - main - ERROR - Unhandled exception: asyncio.run() cannot be called from a running event loop
2025-01-08 00:07:36,154 - main - ERROR - Unhandled exception: asyncio.run() cannot be called from a running event loop
2025-01-08 00:07:36,159 - main - ERROR - Unhandled exception: asyncio.run() cannot be called from a running event loop
2025-01-08 00:07:36,310 - main - ERROR - Unhandled exception: asyncio.run() cannot be called from a running event loop
2025-01-08 00:07:36,317 - main - ERROR - Unhandled exception: asyncio.run() cannot be called from a running event loop
2025-01-08 00:07:36,322 - main - ERROR - Unhandled exception: asyncio.run() cannot be called from a running event loop
2025-01-08 00:07:36,327 - main - ERROR - Unhandled exception: asyncio.run() cannot be called from a running event loop
2025-01-08 00:07:36,479 - main - ERROR - Unhandled exception: asyncio.run() cannot be called from a running event loop
2025-01-08 00:07:36,484 - main - ERROR - Unhandled exception: asyncio.run() cannot be called from a running event loop
2025-01-08 00:07:36,635 - main - ERROR - Unhandled exception: asyncio.run() cannot be called from a running event loop
2025-01-08 00:07:36,640 - main - ERROR - Unhandled exception: asyncio.run() cannot be called from a running event loop
2025-01-08 00:07:36,645 - main - ERROR - Unhandled exception: asyncio.run() cannot be called from a running event loop
2025-01-08 00:07:36,650 - main - ERROR - Unhandled exception: asyncio.run() cannot be called from a running event loop
2025-01-08 00:07:36,790 - main - ERROR - Unhandled exception: asyncio.run() cannot be called from a running event loop
2025-01-08 00:07:36,796 - main - ERROR - Unhandled exception: asyncio.run() cannot be called from a running event loop
2025-01-08 00:07:36,962 - main - ERROR - Unhandled exception: asyncio.run() cannot be called from a running event loop
2025-01-08 00:07:36,967 - main - ERROR - Unhandled exception: asyncio.run() cannot be called from a running event loop
2025-01-08 00:07:36,972 - main - ERROR - Unhandled exception: asyncio.run() cannot be called from a running event loop
2025-01-08 00:07:36,978 - main - ERROR - Unhandled exception: asyncio.run() cannot be called from a running event loop
2025-01-08 00:07:37,117 - main - ERROR - Unhandled exception: asyncio.run() cannot be called from a running event loop
2025-01-08 00:07:37,122 - main - ERROR - Unhandled exception: asyncio.run() cannot be called from a running event loop
2025-01-08 00:07:37,288 - main - ERROR - Unhandled exception: asyncio.run() cannot be called from a running event loop
2025-01-08 00:07:37,293 - main - ERROR - Unhandled exception: asyncio.run() cannot be called from a running event loop
2025-01-08 00:07:37,298 - main - ERROR - Unhandled exception: asyncio.run() cannot be called from a running event loop
2025-01-08 00:07:37,303 - main - ERROR - Unhandled exception: asyncio.run() cannot be called from a running event loop
2025-01-08 00:07:37,430 - main - ERROR - Unhandled exception: asyncio.run() cannot be called from a running event loop
2025-01-08 00:07:37,435 - main - ERROR - Unhandled exception: asyncio.run() cannot be called from a running event loop
2025-01-08 00:07:37,614 - main - ERROR - Unhandled exception: asyncio.run() cannot be called from a running event loop
2025-01-08 00:07:37,619 - main - ERROR - Unhandled exception: asyncio.run() cannot be called from a running event loop
2025-01-08 00:07:37,624 - main - ERROR - Unhandled exception: asyncio.run() cannot be called from a running event loop
2025-01-08 00:07:37,629 - main - ERROR - Unhandled exception: asyncio.run() cannot be called from a running event loop
2025-01-08 00:07:37,754 - main - ERROR - Unhandled exception: asyncio.run() cannot be called from a running event loop
2025-01-08 00:07:37,758 - main - ERROR - Unhandled exception: asyncio.run() cannot be called from a running event loop
2025-01-08 00:07:37,939 - main - ERROR - Unhandled exception: asyncio.run() cannot be called from a running event loop
2025-01-08 00:07:37,945 - main - ERROR - Unhandled exception: asyncio.run() cannot be called from a running event loop
2025-01-08 00:07:37,950 - main - ERROR - Unhandled exception: asyncio.run() cannot be called from a running event loop
2025-01-08 00:07:37,955 - main - ERROR - Unhandled exception: asyncio.run() cannot be called from a running event loop
2025-01-08 00:07:38,064 - main - ERROR - Unhandled exception: asyncio.run() cannot be called from a running event loop
2025-01-08 00:28:25,870 - main - ERROR - Unhandled exception: asyncio.run() cannot be called from a running event loop
2025-01-08 00:28:25,875 - main - ERROR - Unhandled exception: asyncio.run() cannot be called from a running event loop
2025-01-08 00:28:26,670 - main - ERROR - Unhandled exception: asyncio.run() cannot be called from a running event loop
2025-01-08 00:28:26,986 - main - ERROR - Unhandled exception: asyncio.run() cannot be called from a running event loop
2025-01-08 00:28:31,439 - main - ERROR - Unhandled exception: asyncio.run() cannot be called from a running event loop
2025-01-08 00:28:31,752 - main - ERROR - Unhandled exception: asyncio.run() cannot be called from a running event loop
2025-01-08 00:28:32,415 - main - ERROR - Unhandled exception: asyncio.run() cannot be called from a running event loop
2025-01-08 00:28:32,729 - main - ERROR - Unhandled exception: asyncio.run() cannot be called from a running event loop
2025-01-08 00:28:33,443 - main - ERROR - Unhandled exception: asyncio.run() cannot be called from a running event loop
2025-01-08 00:28:33,751 - main - ERROR - Unhandled exception: asyncio.run() cannot be called from a running event loop
2025-01-08 00:28:34,807 - main - ERROR - Unhandled exception: asyncio.run() cannot be called from a running event loop
2025-01-08 00:28:35,108 - main - ERROR - Unhandled exception: asyncio.run() cannot be called from a running event loop
2025-01-08 00:28:35,429 - main - ERROR - Unhandled exception: asyncio.run() cannot be called from a running event loop
2025-01-08 00:28:35,740 - main - ERROR - Unhandled exception: asyncio.run() cannot be called from a running event loop
2025-01-08 00:28:35,972 - main - ERROR - Unhandled exception: asyncio.run() cannot be called from a running event loop
2025-01-08 00:28:35,978 - main - ERROR - Unhandled exception: asyncio.run() cannot be called from a running event loop
2025-01-08 00:28:36,247 - main - ERROR - Unhandled exception: asyncio.run() cannot be called from a running event loop
2025-01-08 00:28:36,560 - main - ERROR - Unhandled exception: asyncio.run() cannot be called from a running event loop
2025-01-08 00:28:36,608 - main - ERROR - Unhandled exception: asyncio.run() cannot be called from a running event loop
2025-01-08 00:28:36,613 - main - ERROR - Unhandled exception: asyncio.run() cannot be called from a running event loop
2025-01-08 00:28:36,965 - main - ERROR - Unhandled exception: asyncio.run() cannot be called from a running event loop
2025-01-08 00:28:36,971 - main - ERROR - Unhandled exception: asyncio.run() cannot be called from a running event loop
2025-01-08 00:28:37,198 - main - ERROR - Unhandled exception: asyncio.run() cannot be called from a running event loop
2025-01-08 00:28:37,205 - main - ERROR - Unhandled exception: asyncio.run() cannot be called from a running event loop
2025-01-08 00:28:37,297 - main - ERROR - Unhandled exception: asyncio.run() cannot be called from a running event loop
2025-01-08 00:28:37,306 - main - ERROR - Unhandled exception: asyncio.run() cannot be called from a running event loop
2025-01-08 00:28:37,667 - main - ERROR - Unhandled exception: asyncio.run() cannot be called from a running event loop
2025-01-08 00:28:37,673 - main - ERROR - Unhandled exception: asyncio.run() cannot be called from a running event loop
2025-01-08 00:28:37,931 - main - ERROR - Unhandled exception: asyncio.run() cannot be called from a running event loop
2025-01-08 00:28:38,040 - main - ERROR - Unhandled exception: asyncio.run() cannot be called from a running event loop
2025-01-08 00:28:38,045 - main - ERROR - Unhandled exception: asyncio.run() cannot be called from a running event loop
2025-01-08 00:28:38,085 - main - ERROR - Unhandled exception: asyncio.run() cannot be called from a running event loop
2025-01-08 00:28:38,159 - main - ERROR - Unhandled exception: asyncio.run() cannot be called from a running event loop
2025-01-08 00:28:38,367 - main - ERROR - Unhandled exception: asyncio.run() cannot be called from a running event loop
2025-01-08 00:28:38,475 - main - ERROR - Unhandled exception: asyncio.run() cannot be called from a running event loop
2025-01-08 00:28:38,480 - main - ERROR - Unhandled exception: asyncio.run() cannot be called from a running event loop
2025-01-08 00:28:38,515 - main - ERROR - Unhandled exception: asyncio.run() cannot be called from a running event loop
2025-01-08 00:28:38,524 - main - ERROR - Unhandled exception: asyncio.run() cannot be called from a running event loop
2025-01-08 00:28:38,675 - main - ERROR - Unhandled exception: asyncio.run() cannot be called from a running event loop
2025-01-08 00:28:38,815 - main - ERROR - Unhandled exception: asyncio.run() cannot be called from a running event loop
2025-01-08 00:28:38,820 - main - ERROR - Unhandled exception: asyncio.run() cannot be called from a running event loop
2025-01-08 00:28:38,862 - main - ERROR - Unhandled exception: asyncio.run() cannot be called from a running event loop
2025-01-08 00:28:38,866 - main - ERROR - Unhandled exception: asyncio.run() cannot be called from a running event loop
2025-01-08 00:28:38,986 - main - ERROR - Unhandled exception: asyncio.run() cannot be called from a running event loop
2025-01-08 00:28:39,001 - main - ERROR - Unhandled exception: asyncio.run() cannot be called from a running event loop
2025-01-08 00:28:39,141 - main - ERROR - Unhandled exception: asyncio.run() cannot be called from a running event loop
2025-01-08 00:28:39,189 - main - ERROR - Unhandled exception: asyncio.run() cannot be called from a running event loop
2025-01-08 00:28:39,235 - main - ERROR - Unhandled exception: asyncio.run() cannot be called from a running event loop
2025-01-08 00:28:39,328 - main - ERROR - Unhandled exception: asyncio.run() cannot be called from a running event loop
2025-01-08 00:28:39,334 - main - ERROR - Unhandled exception: asyncio.run() cannot be called from a running event loop
2025-01-08 00:28:39,352 - main - ERROR - Unhandled exception: asyncio.run() cannot be called from a running event loop
2025-01-08 00:28:39,453 - main - ERROR - Unhandled exception: asyncio.run() cannot be called from a running event loop
2025-01-08 00:28:39,629 - main - ERROR - Unhandled exception: asyncio.run() cannot be called from a running event loop
2025-01-08 00:28:39,656 - main - ERROR - Unhandled exception: asyncio.run() cannot be called from a running event loop
2025-01-08 00:28:39,935 - main - ERROR - Unhandled exception: asyncio.run() cannot be called from a running event loop
2025-01-08 00:28:39,941 - main - ERROR - Unhandled exception: asyncio.run() cannot be called from a running event loop
2025-01-08 00:28:39,982 - main - ERROR - Unhandled exception: asyncio.run() cannot be called from a running event loop
2025-01-08 00:28:39,987 - main - ERROR - Unhandled exception: asyncio.run() cannot be called from a running event loop
2025-01-08 00:28:40,215 - main - ERROR - Unhandled exception: asyncio.run() cannot be called from a running event loop
2025-01-08 00:28:40,222 - main - ERROR - Unhandled exception: asyncio.run() cannot be called from a running event loop
2025-01-08 00:28:40,259 - main - ERROR - Unhandled exception: asyncio.run() cannot be called from a running event loop
2025-01-08 00:28:40,264 - main - ERROR - Unhandled exception: asyncio.run() cannot be called from a running event loop
2025-01-08 00:28:40,309 - main - ERROR - Unhandled exception: asyncio.run() cannot be called from a running event loop
2025-01-08 00:28:40,313 - main - ERROR - Unhandled exception: asyncio.run() cannot be called from a running event loop
2025-01-08 00:28:40,651 - main - ERROR - Unhandled exception: asyncio.run() cannot be called from a running event loop
2025-01-08 00:28:40,657 - main - ERROR - Unhandled exception: asyncio.run() cannot be called from a running event loop
2025-01-08 00:28:40,724 - main - ERROR - Unhandled exception: asyncio.run() cannot be called from a running event loop
2025-01-08 00:28:40,730 - main - ERROR - Unhandled exception: asyncio.run() cannot be called from a running event loop
2025-01-08 00:28:41,642 - main - ERROR - Unhandled exception: asyncio.run() cannot be called from a running event loop
2025-01-08 00:28:41,647 - main - ERROR - Unhandled exception: asyncio.run() cannot be called from a running event loop
2025-01-08 00:28:41,704 - main - ERROR - Unhandled exception: asyncio.run() cannot be called from a running event loop
2025-01-08 00:28:41,709 - main - ERROR - Unhandled exception: asyncio.run() cannot be called from a running event loop
2025-01-08 00:28:41,905 - main - ERROR - Unhandled exception: asyncio.run() cannot be called from a running event loop
2025-01-08 00:28:41,967 - main - ERROR - Unhandled exception: asyncio.run() cannot be called from a running event loop
2025-01-08 00:28:41,973 - main - ERROR - Unhandled exception: asyncio.run() cannot be called from a running event loop
2025-01-08 00:28:42,152 - main - ERROR - Unhandled exception: asyncio.run() cannot be called from a running event loop
2025-01-08 00:28:42,877 - main - ERROR - Unhandled exception: asyncio.run() cannot be called from a running event loop
2025-01-08 00:28:42,882 - main - ERROR - Unhandled exception: asyncio.run() cannot be called from a running event loop
2025-01-08 00:28:43,321 - main - ERROR - Unhandled exception: asyncio.run() cannot be called from a running event loop
2025-01-08 00:28:43,628 - main - ERROR - Unhandled exception: asyncio.run() cannot be called from a running event loop
2025-01-08 00:28:44,047 - main - ERROR - Unhandled exception: asyncio.run() cannot be called from a running event loop
2025-01-08 00:28:44,052 - main - ERROR - Unhandled exception: asyncio.run() cannot be called from a running event loop
2025-01-08 00:28:44,202 - main - ERROR - Unhandled exception: asyncio.run() cannot be called from a running event loop
2025-01-08 00:28:44,207 - main - ERROR - Unhandled exception: asyncio.run() cannot be called from a running event loop
2025-01-08 00:28:44,874 - main - ERROR - Unhandled exception: asyncio.run() cannot be called from a running event loop
2025-01-08 00:28:44,879 - main - ERROR - Unhandled exception: asyncio.run() cannot be called from a running event loop
2025-01-08 00:28:45,053 - main - ERROR - Unhandled exception: asyncio.run() cannot be called from a running event loop
2025-01-08 00:28:45,354 - main - ERROR - Unhandled exception: asyncio.run() cannot be called from a running event loop
2025-01-08 00:28:45,600 - main - ERROR - Unhandled exception: asyncio.run() cannot be called from a running event loop
2025-01-08 00:28:45,912 - main - ERROR - Unhandled exception: asyncio.run() cannot be called from a running event loop
2025-01-08 00:28:45,920 - main - ERROR - Unhandled exception: asyncio.run() cannot be called from a running event loop
2025-01-08 00:28:46,006 - main - ERROR - Unhandled exception: asyncio.run() cannot be called from a running event loop
2025-01-08 00:28:46,094 - main - ERROR - Unhandled exception: asyncio.run() cannot be called from a running event loop
2025-01-08 00:28:46,239 - main - ERROR - Unhandled exception: asyncio.run() cannot be called from a running event loop
2025-01-08 00:28:46,409 - main - ERROR - Unhandled exception: asyncio.run() cannot be called from a running event loop
2025-01-08 00:28:46,414 - main - ERROR - Unhandled exception: asyncio.run() cannot be called from a running event loop
2025-01-08 00:28:46,628 - main - ERROR - Unhandled exception: asyncio.run() cannot be called from a running event loop
2025-01-08 00:28:46,633 - main - ERROR - Unhandled exception: asyncio.run() cannot be called from a running event loop
2025-01-08 00:28:46,979 - main - ERROR - Unhandled exception: asyncio.run() cannot be called from a running event loop
2025-01-08 00:28:47,294 - main - ERROR - Unhandled exception: asyncio.run() cannot be called from a running event loop
2025-01-08 00:28:50,337 - main - ERROR - Unhandled exception: asyncio.run() cannot be called from a running event loop
2025-01-08 00:28:50,342 - main - ERROR - Unhandled exception: asyncio.run() cannot be called from a running event loop
2025-01-08 00:28:50,820 - main - ERROR - Unhandled exception: asyncio.run() cannot be called from a running event loop
2025-01-08 00:28:51,129 - main - ERROR - Unhandled exception: asyncio.run() cannot be called from a running event loop
2025-01-08 00:28:52,929 - main - ERROR - Unhandled exception: asyncio.run() cannot be called from a running event loop
2025-01-08 00:28:53,241 - main - ERROR - Unhandled exception: asyncio.run() cannot be called from a running event loop
2025-01-08 00:28:54,218 - main - ERROR - Unhandled exception: asyncio.run() cannot be called from a running event loop
2025-01-08 00:28:54,224 - main - ERROR - Unhandled exception: asyncio.run() cannot be called from a running event loop
2025-01-08 00:33:18,722 - main - ERROR - Unhandled exception: asyncio.run() cannot be called from a running event loop
2025-01-08 00:33:18,729 - main - ERROR - Unhandled exception: asyncio.run() cannot be called from a running event loop
2025-01-08 00:33:18,985 - main - ERROR - Unhandled exception: asyncio.run() cannot be called from a running event loop
2025-01-08 00:33:19,127 - main - ERROR - Unhandled exception: asyncio.run() cannot be called from a running event loop
2025-01-08 00:33:19,363 - main - ERROR - Unhandled exception: asyncio.run() cannot be called from a running event loop
2025-01-08 00:33:19,669 - main - ERROR - Unhandled exception: asyncio.run() cannot be called from a running event loop
2025-01-08 00:33:19,677 - main - ERROR - Unhandled exception: asyncio.run() cannot be called from a running event loop
2025-01-08 00:33:19,779 - main - ERROR - Unhandled exception: asyncio.run() cannot be called from a running event loop
2025-01-08 00:39:27,712 - main - ERROR - Unhandled exception: asyncio.run() cannot be called from a running event loop
2025-01-08 00:39:27,718 - main - ERROR - Unhandled exception: asyncio.run() cannot be called from a running event loop
2025-01-08 00:39:27,733 - main - ERROR - Unhandled exception: asyncio.run() cannot be called from a running event loop
2025-01-08 00:39:28,041 - main - ERROR - Unhandled exception: asyncio.run() cannot be called from a running event loop
2025-01-08 00:39:28,049 - main - ERROR - Unhandled exception: asyncio.run() cannot be called from a running event loop
2025-01-08 00:39:28,057 - main - ERROR - Unhandled exception: asyncio.run() cannot be called from a running event loop
2025-01-08 00:39:28,065 - main - ERROR - Unhandled exception: asyncio.run() cannot be called from a running event loop
2025-01-08 00:39:28,103 - main - ERROR - Unhandled exception: asyncio.run() cannot be called from a running event loop
2025-01-08 00:39:28,109 - main - ERROR - Unhandled exception: asyncio.run() cannot be called from a running event loop
2025-01-08 00:39:28,367 - main - ERROR - Unhandled exception: asyncio.run() cannot be called from a running event loop
2025-01-08 00:39:28,373 - main - ERROR - Unhandled exception: asyncio.run() cannot be called from a running event loop
2025-01-08 00:39:28,384 - main - ERROR - Unhandled exception: asyncio.run() cannot be called from a running event loop
2025-01-08 00:39:28,420 - main - ERROR - Unhandled exception: asyncio.run() cannot be called from a running event loop
2025-01-08 00:39:28,693 - main - ERROR - Unhandled exception: asyncio.run() cannot be called from a running event loop
2025-01-08 00:39:28,699 - main - ERROR - Unhandled exception: asyncio.run() cannot be called from a running event loop
2025-01-08 00:39:28,705 - main - ERROR - Unhandled exception: asyncio.run() cannot be called from a running event loop
2025-01-08 00:39:28,709 - main - ERROR - Unhandled exception: asyncio.run() cannot be called from a running event loop
2025-01-08 00:39:28,714 - main - ERROR - Unhandled exception: asyncio.run() cannot be called from a running event loop
2025-01-08 00:39:28,740 - main - ERROR - Unhandled exception: asyncio.run() cannot be called from a running event loop
2025-01-08 00:39:29,037 - main - ERROR - Unhandled exception: asyncio.run() cannot be called from a running event loop
2025-01-08 00:39:29,043 - main - ERROR - Unhandled exception: asyncio.run() cannot be called from a running event loop
2025-01-08 00:39:29,049 - main - ERROR - Unhandled exception: asyncio.run() cannot be called from a running event loop
2025-01-08 00:39:29,055 - main - ERROR - Unhandled exception: asyncio.run() cannot be called from a running event loop
2025-01-08 00:39:29,060 - main - ERROR - Unhandled exception: asyncio.run() cannot be called from a running event loop
2025-01-08 00:39:29,067 - main - ERROR - Unhandled exception: asyncio.run() cannot be called from a running event loop
2025-01-08 00:39:29,379 - main - ERROR - Unhandled exception: asyncio.run() cannot be called from a running event loop
2025-01-08 00:39:29,385 - main - ERROR - Unhandled exception: asyncio.run() cannot be called from a running event loop
2025-01-08 00:39:29,391 - main - ERROR - Unhandled exception: asyncio.run() cannot be called from a running event loop
2025-01-08 00:39:29,397 - main - ERROR - Unhandled exception: asyncio.run() cannot be called from a running event loop
2025-01-08 00:39:29,403 - main - ERROR - Unhandled exception: asyncio.run() cannot be called from a running event loop
2025-01-08 00:39:29,410 - main - ERROR - Unhandled exception: asyncio.run() cannot be called from a running event loop
2025-01-08 00:39:29,721 - main - ERROR - Unhandled exception: asyncio.run() cannot be called from a running event loop
2025-01-08 00:39:29,727 - main - ERROR - Unhandled exception: asyncio.run() cannot be called from a running event loop
2025-01-08 00:39:29,733 - main - ERROR - Unhandled exception: asyncio.run() cannot be called from a running event loop
2025-01-08 00:39:29,739 - main - ERROR - Unhandled exception: asyncio.run() cannot be called from a running event loop
2025-01-08 00:39:29,745 - main - ERROR - Unhandled exception: asyncio.run() cannot be called from a running event loop
2025-01-08 00:39:29,751 - main - ERROR - Unhandled exception: asyncio.run() cannot be called from a running event loop
2025-01-08 00:39:30,063 - main - ERROR - Unhandled exception: asyncio.run() cannot be called from a running event loop
2025-01-08 00:39:30,070 - main - ERROR - Unhandled exception: asyncio.run() cannot be called from a running event loop
2025-01-08 00:39:30,075 - main - ERROR - Unhandled exception: asyncio.run() cannot be called from a running event loop
2025-01-08 00:39:30,081 - main - ERROR - Unhandled exception: asyncio.run() cannot be called from a running event loop
2025-01-08 00:39:30,087 - main - ERROR - Unhandled exception: asyncio.run() cannot be called from a running event loop
2025-01-08 00:39:30,092 - main - ERROR - Unhandled exception: asyncio.run() cannot be called from a running event loop
2025-01-08 00:39:30,402 - main - ERROR - Unhandled exception: asyncio.run() cannot be called from a running event loop
2025-01-08 00:39:30,408 - main - ERROR - Unhandled exception: asyncio.run() cannot be called from a running event loop
2025-01-08 00:39:30,415 - main - ERROR - Unhandled exception: asyncio.run() cannot be called from a running event loop
2025-01-08 00:39:30,421 - main - ERROR - Unhandled exception: asyncio.run() cannot be called from a running event loop
2025-01-08 00:39:30,429 - main - ERROR - Unhandled exception: asyncio.run() cannot be called from a running event loop
2025-01-08 00:39:30,436 - main - ERROR - Unhandled exception: asyncio.run() cannot be called from a running event loop
2025-01-08 00:39:30,745 - main - ERROR - Unhandled exception: asyncio.run() cannot be called from a running event loop
2025-01-08 00:39:30,752 - main - ERROR - Unhandled exception: asyncio.run() cannot be called from a running event loop
2025-01-08 00:39:30,758 - main - ERROR - Unhandled exception: asyncio.run() cannot be called from a running event loop
2025-01-08 00:39:30,765 - main - ERROR - Unhandled exception: asyncio.run() cannot be called from a running event loop
2025-01-08 00:39:30,771 - main - ERROR - Unhandled exception: asyncio.run() cannot be called from a running event loop
2025-01-08 00:39:30,777 - main - ERROR - Unhandled exception: asyncio.run() cannot be called from a running event loop
2025-01-08 00:39:31,088 - main - ERROR - Unhandled exception: asyncio.run() cannot be called from a running event loop
2025-01-08 00:39:31,094 - main - ERROR - Unhandled exception: asyncio.run() cannot be called from a running event loop
2025-01-08 00:39:31,100 - main - ERROR - Unhandled exception: asyncio.run() cannot be called from a running event loop
2025-01-08 00:39:31,106 - main - ERROR - Unhandled exception: asyncio.run() cannot be called from a running event loop
2025-01-08 00:39:31,111 - main - ERROR - Unhandled exception: asyncio.run() cannot be called from a running event loop
2025-01-08 00:39:31,118 - main - ERROR - Unhandled exception: asyncio.run() cannot be called from a running event loop
2025-01-08 00:39:31,429 - main - ERROR - Unhandled exception: asyncio.run() cannot be called from a running event loop
2025-01-08 00:39:31,437 - main - ERROR - Unhandled exception: asyncio.run() cannot be called from a running event loop
2025-01-08 00:39:31,443 - main - ERROR - Unhandled exception: asyncio.run() cannot be called from a running event loop
2025-01-08 00:39:31,450 - main - ERROR - Unhandled exception: asyncio.run() cannot be called from a running event loop
2025-01-08 00:39:31,456 - main - ERROR - Unhandled exception: asyncio.run() cannot be called from a running event loop
2025-01-08 00:39:31,463 - main - ERROR - Unhandled exception: asyncio.run() cannot be called from a running event loop
2025-01-08 00:39:31,787 - main - ERROR - Unhandled exception: asyncio.run() cannot be called from a running event loop
2025-01-08 00:39:31,792 - main - ERROR - Unhandled exception: asyncio.run() cannot be called from a running event loop
2025-01-08 00:39:31,799 - main - ERROR - Unhandled exception: asyncio.run() cannot be called from a running event loop
2025-01-08 00:39:31,804 - main - ERROR - Unhandled exception: asyncio.run() cannot be called from a running event loop
2025-01-08 00:39:31,809 - main - ERROR - Unhandled exception: asyncio.run() cannot be called from a running event loop
2025-01-08 00:39:31,820 - main - ERROR - Unhandled exception: asyncio.run() cannot be called from a running event loop
2025-01-08 00:39:32,128 - main - ERROR - Unhandled exception: asyncio.run() cannot be called from a running event loop
2025-01-08 00:39:32,134 - main - ERROR - Unhandled exception: asyncio.run() cannot be called from a running event loop
2025-01-08 00:39:32,141 - main - ERROR - Unhandled exception: asyncio.run() cannot be called from a running event loop
2025-01-08 00:39:32,147 - main - ERROR - Unhandled exception: asyncio.run() cannot be called from a running event loop
2025-01-08 00:39:32,153 - main - ERROR - Unhandled exception: asyncio.run() cannot be called from a running event loop
2025-01-08 00:39:32,159 - main - ERROR - Unhandled exception: asyncio.run() cannot be called from a running event loop
2025-01-08 00:39:32,469 - main - ERROR - Unhandled exception: asyncio.run() cannot be called from a running event loop
2025-01-08 00:39:32,475 - main - ERROR - Unhandled exception: asyncio.run() cannot be called from a running event loop
2025-01-08 00:39:32,481 - main - ERROR - Unhandled exception: asyncio.run() cannot be called from a running event loop
2025-01-08 00:39:32,487 - main - ERROR - Unhandled exception: asyncio.run() cannot be called from a running event loop
2025-01-08 00:39:32,491 - main - ERROR - Unhandled exception: asyncio.run() cannot be called from a running event loop
2025-01-08 00:39:32,497 - main - ERROR - Unhandled exception: asyncio.run() cannot be called from a running event loop
2025-01-08 00:39:32,809 - main - ERROR - Unhandled exception: asyncio.run() cannot be called from a running event loop
2025-01-08 00:39:32,815 - main - ERROR - Unhandled exception: asyncio.run() cannot be called from a running event loop
2025-01-08 00:39:32,821 - main - ERROR - Unhandled exception: asyncio.run() cannot be called from a running event loop
2025-01-08 00:39:32,827 - main - ERROR - Unhandled exception: asyncio.run() cannot be called from a running event loop
2025-01-08 00:39:32,832 - main - ERROR - Unhandled exception: asyncio.run() cannot be called from a running event loop
2025-01-08 00:39:32,838 - main - ERROR - Unhandled exception: asyncio.run() cannot be called from a running event loop
2025-01-08 00:39:33,151 - main - ERROR - Unhandled exception: asyncio.run() cannot be called from a running event loop
2025-01-08 00:39:33,158 - main - ERROR - Unhandled exception: asyncio.run() cannot be called from a running event loop
2025-01-08 00:39:33,164 - main - ERROR - Unhandled exception: asyncio.run() cannot be called from a running event loop
2025-01-08 00:39:33,170 - main - ERROR - Unhandled exception: asyncio.run() cannot be called from a running event loop
2025-01-08 00:39:33,176 - main - ERROR - Unhandled exception: asyncio.run() cannot be called from a running event loop
2025-01-08 00:39:33,183 - main - ERROR - Unhandled exception: asyncio.run() cannot be called from a running event loop
2025-01-08 00:39:33,493 - main - ERROR - Unhandled exception: asyncio.run() cannot be called from a running event loop
2025-01-08 00:39:33,499 - main - ERROR - Unhandled exception: asyncio.run() cannot be called from a running event loop
2025-01-08 00:39:33,506 - main - ERROR - Unhandled exception: asyncio.run() cannot be called from a running event loop
2025-01-08 00:39:33,512 - main - ERROR - Unhandled exception: asyncio.run() cannot be called from a running event loop
2025-01-08 00:39:33,519 - main - ERROR - Unhandled exception: asyncio.run() cannot be called from a running event loop
2025-01-08 00:39:33,525 - main - ERROR - Unhandled exception: asyncio.run() cannot be called from a running event loop
2025-01-08 00:39:33,836 - main - ERROR - Unhandled exception: asyncio.run() cannot be called from a running event loop
2025-01-08 00:39:33,842 - main - ERROR - Unhandled exception: asyncio.run() cannot be called from a running event loop
2025-01-08 00:39:33,849 - main - ERROR - Unhandled exception: asyncio.run() cannot be called from a running event loop
2025-01-08 00:39:33,855 - main - ERROR - Unhandled exception: asyncio.run() cannot be called from a running event loop
2025-01-08 00:39:33,860 - main - ERROR - Unhandled exception: asyncio.run() cannot be called from a running event loop
2025-01-08 00:39:33,866 - main - ERROR - Unhandled exception: asyncio.run() cannot be called from a running event loop
2025-01-08 00:39:34,177 - main - ERROR - Unhandled exception: asyncio.run() cannot be called from a running event loop
2025-01-08 00:39:34,184 - main - ERROR - Unhandled exception: asyncio.run() cannot be called from a running event loop
2025-01-08 00:39:34,192 - main - ERROR - Unhandled exception: asyncio.run() cannot be called from a running event loop
2025-01-08 00:39:34,200 - main - ERROR - Unhandled exception: asyncio.run() cannot be called from a running event loop
2025-01-08 00:39:34,206 - main - ERROR - Unhandled exception: asyncio.run() cannot be called from a running event loop
2025-01-08 00:39:34,211 - main - ERROR - Unhandled exception: asyncio.run() cannot be called from a running event loop
2025-01-08 00:39:34,521 - main - ERROR - Unhandled exception: asyncio.run() cannot be called from a running event loop
2025-01-08 00:39:34,527 - main - ERROR - Unhandled exception: asyncio.run() cannot be called from a running event loop
2025-01-08 00:39:34,534 - main - ERROR - Unhandled exception: asyncio.run() cannot be called from a running event loop
2025-01-08 00:39:34,539 - main - ERROR - Unhandled exception: asyncio.run() cannot be called from a running event loop
2025-01-08 00:39:34,544 - main - ERROR - Unhandled exception: asyncio.run() cannot be called from a running event loop
2025-01-08 00:39:34,551 - main - ERROR - Unhandled exception: asyncio.run() cannot be called from a running event loop
2025-01-08 00:39:34,862 - main - ERROR - Unhandled exception: asyncio.run() cannot be called from a running event loop
2025-01-08 00:39:34,868 - main - ERROR - Unhandled exception: asyncio.run() cannot be called from a running event loop
2025-01-08 00:39:34,873 - main - ERROR - Unhandled exception: asyncio.run() cannot be called from a running event loop
2025-01-08 00:39:34,879 - main - ERROR - Unhandled exception: asyncio.run() cannot be called from a running event loop
2025-01-08 00:39:34,885 - main - ERROR - Unhandled exception: asyncio.run() cannot be called from a running event loop
2025-01-08 00:39:34,891 - main - ERROR - Unhandled exception: asyncio.run() cannot be called from a running event loop
2025-01-08 00:39:35,205 - main - ERROR - Unhandled exception: asyncio.run() cannot be called from a running event loop
2025-01-08 00:39:35,211 - main - ERROR - Unhandled exception: asyncio.run() cannot be called from a running event loop
2025-01-08 00:39:35,217 - main - ERROR - Unhandled exception: asyncio.run() cannot be called from a running event loop
2025-01-08 00:39:35,224 - main - ERROR - Unhandled exception: asyncio.run() cannot be called from a running event loop
2025-01-08 00:39:35,231 - main - ERROR - Unhandled exception: asyncio.run() cannot be called from a running event loop
2025-01-08 00:39:35,238 - main - ERROR - Unhandled exception: asyncio.run() cannot be called from a running event loop
2025-01-08 00:39:35,547 - main - ERROR - Unhandled exception: asyncio.run() cannot be called from a running event loop
2025-01-08 00:39:35,555 - main - ERROR - Unhandled exception: asyncio.run() cannot be called from a running event loop
2025-01-08 00:39:35,562 - main - ERROR - Unhandled exception: asyncio.run() cannot be called from a running event loop
2025-01-08 00:39:35,569 - main - ERROR - Unhandled exception: asyncio.run() cannot be called from a running event loop
2025-01-08 00:39:35,576 - main - ERROR - Unhandled exception: asyncio.run() cannot be called from a running event loop
2025-01-08 00:39:35,583 - main - ERROR - Unhandled exception: asyncio.run() cannot be called from a running event loop
2025-01-08 00:39:35,904 - main - ERROR - Unhandled exception: asyncio.run() cannot be called from a running event loop
2025-01-08 00:39:46,118 - main - ERROR - Unhandled exception: asyncio.run() cannot be called from a running event loop
2025-01-08 00:39:46,419 - main - ERROR - Unhandled exception: asyncio.run() cannot be called from a running event loop
2025-01-08 00:39:46,450 - main - ERROR - Unhandled exception: asyncio.run() cannot be called from a running event loop
2025-01-08 00:39:46,456 - main - ERROR - Unhandled exception: asyncio.run() cannot be called from a running event loop
2025-01-08 00:39:46,462 - main - ERROR - Unhandled exception: asyncio.run() cannot be called from a running event loop
2025-01-08 00:39:46,468 - main - ERROR - Unhandled exception: asyncio.run() cannot be called from a running event loop
2025-01-08 00:39:46,473 - main - ERROR - Unhandled exception: asyncio.run() cannot be called from a running event loop
2025-01-08 00:39:46,728 - main - ERROR - Unhandled exception: asyncio.run() cannot be called from a running event loop
2025-01-08 00:39:46,773 - main - ERROR - Unhandled exception: asyncio.run() cannot be called from a running event loop
2025-01-08 00:39:46,778 - main - ERROR - Unhandled exception: asyncio.run() cannot be called from a running event loop
2025-01-08 00:39:46,786 - main - ERROR - Unhandled exception: asyncio.run() cannot be called from a running event loop
2025-01-08 00:39:46,791 - main - ERROR - Unhandled exception: asyncio.run() cannot be called from a running event loop
2025-01-08 00:39:46,796 - main - ERROR - Unhandled exception: asyncio.run() cannot be called from a running event loop
2025-01-08 00:39:47,041 - main - ERROR - Unhandled exception: asyncio.run() cannot be called from a running event loop
2025-01-08 00:39:47,088 - main - ERROR - Unhandled exception: asyncio.run() cannot be called from a running event loop
2025-01-08 00:39:47,093 - main - ERROR - Unhandled exception: asyncio.run() cannot be called from a running event loop
2025-01-08 00:39:47,121 - main - ERROR - Unhandled exception: asyncio.run() cannot be called from a running event loop
2025-01-08 00:39:47,127 - main - ERROR - Unhandled exception: asyncio.run() cannot be called from a running event loop
2025-01-08 00:39:47,133 - main - ERROR - Unhandled exception: asyncio.run() cannot be called from a running event loop
2025-01-08 00:39:47,351 - main - ERROR - Unhandled exception: asyncio.run() cannot be called from a running event loop
2025-01-08 00:39:47,413 - main - ERROR - Unhandled exception: asyncio.run() cannot be called from a running event loop
2025-01-08 00:39:47,420 - main - ERROR - Unhandled exception: asyncio.run() cannot be called from a running event loop
2025-01-08 00:39:47,445 - main - ERROR - Unhandled exception: asyncio.run() cannot be called from a running event loop
2025-01-08 00:39:47,451 - main - ERROR - Unhandled exception: asyncio.run() cannot be called from a running event loop
2025-01-08 00:39:47,456 - main - ERROR - Unhandled exception: asyncio.run() cannot be called from a running event loop
2025-01-08 00:39:47,663 - main - ERROR - Unhandled exception: asyncio.run() cannot be called from a running event loop
2025-01-08 00:39:47,739 - main - ERROR - Unhandled exception: asyncio.run() cannot be called from a running event loop
2025-01-08 00:39:47,746 - main - ERROR - Unhandled exception: asyncio.run() cannot be called from a running event loop
2025-01-08 00:39:47,771 - main - ERROR - Unhandled exception: asyncio.run() cannot be called from a running event loop
2025-01-08 00:39:47,776 - main - ERROR - Unhandled exception: asyncio.run() cannot be called from a running event loop
2025-01-08 00:39:47,782 - main - ERROR - Unhandled exception: asyncio.run() cannot be called from a running event loop
2025-01-08 00:39:47,989 - main - ERROR - Unhandled exception: asyncio.run() cannot be called from a running event loop
2025-01-08 00:39:48,066 - main - ERROR - Unhandled exception: asyncio.run() cannot be called from a running event loop
2025-01-08 00:39:48,071 - main - ERROR - Unhandled exception: asyncio.run() cannot be called from a running event loop
2025-01-08 00:39:48,098 - main - ERROR - Unhandled exception: asyncio.run() cannot be called from a running event loop
2025-01-08 00:39:48,104 - main - ERROR - Unhandled exception: asyncio.run() cannot be called from a running event loop
2025-01-08 00:39:48,109 - main - ERROR - Unhandled exception: asyncio.run() cannot be called from a running event loop
2025-01-08 00:39:48,298 - main - ERROR - Unhandled exception: asyncio.run() cannot be called from a running event loop
2025-01-08 00:39:48,392 - main - ERROR - Unhandled exception: asyncio.run() cannot be called from a running event loop
2025-01-08 00:39:48,399 - main - ERROR - Unhandled exception: asyncio.run() cannot be called from a running event loop
2025-01-08 00:39:48,423 - main - ERROR - Unhandled exception: asyncio.run() cannot be called from a running event loop
2025-01-08 00:39:48,428 - main - ERROR - Unhandled exception: asyncio.run() cannot be called from a running event loop
2025-01-08 00:39:48,433 - main - ERROR - Unhandled exception: asyncio.run() cannot be called from a running event loop
2025-01-08 00:39:48,608 - main - ERROR - Unhandled exception: asyncio.run() cannot be called from a running event loop
2025-01-08 00:39:48,718 - main - ERROR - Unhandled exception: asyncio.run() cannot be called from a running event loop
2025-01-08 00:39:48,724 - main - ERROR - Unhandled exception: asyncio.run() cannot be called from a running event loop
2025-01-08 00:39:48,748 - main - ERROR - Unhandled exception: asyncio.run() cannot be called from a running event loop
2025-01-08 00:39:48,754 - main - ERROR - Unhandled exception: asyncio.run() cannot be called from a running event loop
2025-01-08 00:39:48,759 - main - ERROR - Unhandled exception: asyncio.run() cannot be called from a running event loop
2025-01-08 00:39:48,919 - main - ERROR - Unhandled exception: asyncio.run() cannot be called from a running event loop
2025-01-08 00:39:49,043 - main - ERROR - Unhandled exception: asyncio.run() cannot be called from a running event loop
2025-01-08 00:39:49,050 - main - ERROR - Unhandled exception: asyncio.run() cannot be called from a running event loop
2025-01-08 00:39:49,074 - main - ERROR - Unhandled exception: asyncio.run() cannot be called from a running event loop
2025-01-08 00:39:49,080 - main - ERROR - Unhandled exception: asyncio.run() cannot be called from a running event loop
2025-01-08 00:39:49,086 - main - ERROR - Unhandled exception: asyncio.run() cannot be called from a running event loop
2025-01-08 00:39:49,230 - main - ERROR - Unhandled exception: asyncio.run() cannot be called from a running event loop
2025-01-08 00:39:49,369 - main - ERROR - Unhandled exception: asyncio.run() cannot be called from a running event loop
2025-01-08 00:39:49,374 - main - ERROR - Unhandled exception: asyncio.run() cannot be called from a running event loop
2025-01-08 00:39:49,402 - main - ERROR - Unhandled exception: asyncio.run() cannot be called from a running event loop
2025-01-08 00:39:49,407 - main - ERROR - Unhandled exception: asyncio.run() cannot be called from a running event loop
2025-01-08 00:39:49,413 - main - ERROR - Unhandled exception: asyncio.run() cannot be called from a running event loop
2025-01-08 00:39:49,540 - main - ERROR - Unhandled exception: asyncio.run() cannot be called from a running event loop
2025-01-08 00:39:49,681 - main - ERROR - Unhandled exception: asyncio.run() cannot be called from a running event loop
2025-01-08 00:39:49,689 - main - ERROR - Unhandled exception: asyncio.run() cannot be called from a running event loop
2025-01-08 00:39:49,728 - main - ERROR - Unhandled exception: asyncio.run() cannot be called from a running event loop
2025-01-08 00:39:49,733 - main - ERROR - Unhandled exception: asyncio.run() cannot be called from a running event loop
2025-01-08 00:39:49,739 - main - ERROR - Unhandled exception: asyncio.run() cannot be called from a running event loop
2025-01-08 00:39:49,853 - main - ERROR - Unhandled exception: asyncio.run() cannot be called from a running event loop
2025-01-08 00:39:50,008 - main - ERROR - Unhandled exception: asyncio.run() cannot be called from a running event loop
2025-01-08 00:39:50,014 - main - ERROR - Unhandled exception: asyncio.run() cannot be called from a running event loop
2025-01-08 00:39:50,054 - main - ERROR - Unhandled exception: asyncio.run() cannot be called from a running event loop
2025-01-08 00:39:50,059 - main - ERROR - Unhandled exception: asyncio.run() cannot be called from a running event loop
2025-01-08 00:39:50,067 - main - ERROR - Unhandled exception: asyncio.run() cannot be called from a running event loop
2025-01-08 00:39:50,163 - main - ERROR - Unhandled exception: asyncio.run() cannot be called from a running event loop
2025-01-08 00:39:50,334 - main - ERROR - Unhandled exception: asyncio.run() cannot be called from a running event loop
2025-01-08 00:39:50,341 - main - ERROR - Unhandled exception: asyncio.run() cannot be called from a running event loop
2025-01-08 00:39:50,381 - main - ERROR - Unhandled exception: asyncio.run() cannot be called from a running event loop
2025-01-08 00:39:50,388 - main - ERROR - Unhandled exception: asyncio.run() cannot be called from a running event loop
2025-01-08 00:39:50,394 - main - ERROR - Unhandled exception: asyncio.run() cannot be called from a running event loop
2025-01-08 00:39:50,473 - main - ERROR - Unhandled exception: asyncio.run() cannot be called from a running event loop
2025-01-08 00:39:50,660 - main - ERROR - Unhandled exception: asyncio.run() cannot be called from a running event loop
2025-01-08 00:39:50,667 - main - ERROR - Unhandled exception: asyncio.run() cannot be called from a running event loop
2025-01-08 00:39:50,707 - main - ERROR - Unhandled exception: asyncio.run() cannot be called from a running event loop
2025-01-08 00:39:50,714 - main - ERROR - Unhandled exception: asyncio.run() cannot be called from a running event loop
2025-01-08 00:39:50,721 - main - ERROR - Unhandled exception: asyncio.run() cannot be called from a running event loop
2025-01-08 00:39:50,785 - main - ERROR - Unhandled exception: asyncio.run() cannot be called from a running event loop
2025-01-08 00:39:50,987 - main - ERROR - Unhandled exception: asyncio.run() cannot be called from a running event loop
2025-01-08 00:39:50,993 - main - ERROR - Unhandled exception: asyncio.run() cannot be called from a running event loop
2025-01-08 00:39:51,034 - main - ERROR - Unhandled exception: asyncio.run() cannot be called from a running event loop
2025-01-08 00:39:51,039 - main - ERROR - Unhandled exception: asyncio.run() cannot be called from a running event loop
2025-01-08 00:39:51,045 - main - ERROR - Unhandled exception: asyncio.run() cannot be called from a running event loop
2025-01-08 00:39:51,097 - main - ERROR - Unhandled exception: asyncio.run() cannot be called from a running event loop
2025-01-08 00:39:51,314 - main - ERROR - Unhandled exception: asyncio.run() cannot be called from a running event loop
2025-01-08 00:39:51,321 - main - ERROR - Unhandled exception: asyncio.run() cannot be called from a running event loop
2025-01-08 00:39:51,360 - main - ERROR - Unhandled exception: asyncio.run() cannot be called from a running event loop
2025-01-08 00:39:51,366 - main - ERROR - Unhandled exception: asyncio.run() cannot be called from a running event loop
2025-01-08 00:39:51,372 - main - ERROR - Unhandled exception: asyncio.run() cannot be called from a running event loop
2025-01-08 00:39:51,406 - main - ERROR - Unhandled exception: asyncio.run() cannot be called from a running event loop
2025-01-08 00:39:51,640 - main - ERROR - Unhandled exception: asyncio.run() cannot be called from a running event loop
2025-01-08 00:39:51,646 - main - ERROR - Unhandled exception: asyncio.run() cannot be called from a running event loop
2025-01-08 00:39:51,688 - main - ERROR - Unhandled exception: asyncio.run() cannot be called from a running event loop
2025-01-08 00:39:51,693 - main - ERROR - Unhandled exception: asyncio.run() cannot be called from a running event loop
2025-01-08 00:39:51,699 - main - ERROR - Unhandled exception: asyncio.run() cannot be called from a running event loop
2025-01-08 00:39:51,719 - main - ERROR - Unhandled exception: asyncio.run() cannot be called from a running event loop
2025-01-08 00:39:51,967 - main - ERROR - Unhandled exception: asyncio.run() cannot be called from a running event loop
2025-01-08 00:39:51,974 - main - ERROR - Unhandled exception: asyncio.run() cannot be called from a running event loop
2025-01-08 00:39:52,014 - main - ERROR - Unhandled exception: asyncio.run() cannot be called from a running event loop
2025-01-08 00:39:52,020 - main - ERROR - Unhandled exception: asyncio.run() cannot be called from a running event loop
2025-01-08 00:39:52,026 - main - ERROR - Unhandled exception: asyncio.run() cannot be called from a running event loop
2025-01-08 00:39:52,033 - main - ERROR - Unhandled exception: asyncio.run() cannot be called from a running event loop
2025-01-08 00:39:52,293 - main - ERROR - Unhandled exception: asyncio.run() cannot be called from a running event loop
2025-01-08 00:39:52,299 - main - ERROR - Unhandled exception: asyncio.run() cannot be called from a running event loop
2025-01-08 00:39:52,340 - main - ERROR - Unhandled exception: asyncio.run() cannot be called from a running event loop
2025-01-08 00:39:52,346 - main - ERROR - Unhandled exception: asyncio.run() cannot be called from a running event loop
2025-01-08 00:39:52,354 - main - ERROR - Unhandled exception: asyncio.run() cannot be called from a running event loop
2025-01-08 00:39:52,359 - main - ERROR - Unhandled exception: asyncio.run() cannot be called from a running event loop
2025-01-08 00:39:52,620 - main - ERROR - Unhandled exception: asyncio.run() cannot be called from a running event loop
2025-01-08 00:39:52,626 - main - ERROR - Unhandled exception: asyncio.run() cannot be called from a running event loop
2025-01-08 00:39:52,682 - main - ERROR - Unhandled exception: asyncio.run() cannot be called from a running event loop
2025-01-08 00:39:52,689 - main - ERROR - Unhandled exception: asyncio.run() cannot be called from a running event loop
2025-01-08 00:39:52,694 - main - ERROR - Unhandled exception: asyncio.run() cannot be called from a running event loop
2025-01-08 00:39:52,700 - main - ERROR - Unhandled exception: asyncio.run() cannot be called from a running event loop
2025-01-08 00:39:52,946 - main - ERROR - Unhandled exception: asyncio.run() cannot be called from a running event loop
2025-01-08 00:39:52,952 - main - ERROR - Unhandled exception: asyncio.run() cannot be called from a running event loop
2025-01-08 00:39:53,009 - main - ERROR - Unhandled exception: asyncio.run() cannot be called from a running event loop
2025-01-08 00:39:53,016 - main - ERROR - Unhandled exception: asyncio.run() cannot be called from a running event loop
2025-01-08 00:39:53,022 - main - ERROR - Unhandled exception: asyncio.run() cannot be called from a running event loop
2025-01-08 00:39:53,028 - main - ERROR - Unhandled exception: asyncio.run() cannot be called from a running event loop
2025-01-08 00:39:53,272 - main - ERROR - Unhandled exception: asyncio.run() cannot be called from a running event loop
2025-01-08 00:39:53,278 - main - ERROR - Unhandled exception: asyncio.run() cannot be called from a running event loop
2025-01-08 00:39:53,351 - main - ERROR - Unhandled exception: asyncio.run() cannot be called from a running event loop
2025-01-08 00:39:53,357 - main - ERROR - Unhandled exception: asyncio.run() cannot be called from a running event loop
2025-01-08 00:39:53,363 - main - ERROR - Unhandled exception: asyncio.run() cannot be called from a running event loop
2025-01-08 00:39:53,368 - main - ERROR - Unhandled exception: asyncio.run() cannot be called from a running event loop
2025-01-08 00:39:53,598 - main - ERROR - Unhandled exception: asyncio.run() cannot be called from a running event loop
2025-01-08 00:39:53,604 - main - ERROR - Unhandled exception: asyncio.run() cannot be called from a running event loop
2025-01-08 00:39:53,676 - main - ERROR - Unhandled exception: asyncio.run() cannot be called from a running event loop
2025-01-08 00:39:53,682 - main - ERROR - Unhandled exception: asyncio.run() cannot be called from a running event loop
2025-01-08 00:39:53,687 - main - ERROR - Unhandled exception: asyncio.run() cannot be called from a running event loop
2025-01-08 00:39:53,693 - main - ERROR - Unhandled exception: asyncio.run() cannot be called from a running event loop
2025-01-08 00:39:53,924 - main - ERROR - Unhandled exception: asyncio.run() cannot be called from a running event loop
2025-01-08 00:39:53,931 - main - ERROR - Unhandled exception: asyncio.run() cannot be called from a running event loop
2025-01-08 00:39:54,003 - main - ERROR - Unhandled exception: asyncio.run() cannot be called from a running event loop
2025-01-08 00:39:54,009 - main - ERROR - Unhandled exception: asyncio.run() cannot be called from a running event loop
2025-01-08 00:39:54,015 - main - ERROR - Unhandled exception: asyncio.run() cannot be called from a running event loop
2025-01-08 00:39:54,034 - main - ERROR - Unhandled exception: asyncio.run() cannot be called from a running event loop
2025-01-08 00:39:54,240 - main - ERROR - Unhandled exception: asyncio.run() cannot be called from a running event loop
2025-01-08 00:39:54,325 - main - ERROR - Unhandled exception: asyncio.run() cannot be called from a running event loop
2025-01-08 00:39:54,423 - main - ERROR - Unhandled exception: asyncio.run() cannot be called from a running event loop
2025-01-08 00:39:54,430 - main - ERROR - Unhandled exception: asyncio.run() cannot be called from a running event loop
2025-01-08 00:39:55,923 - main - ERROR - Unhandled exception: asyncio.run() cannot be called from a running event loop
2025-01-08 00:39:55,930 - main - ERROR - Unhandled exception: asyncio.run() cannot be called from a running event loop
2025-01-08 00:39:56,150 - main - ERROR - Unhandled exception: asyncio.run() cannot be called from a running event loop
2025-01-08 00:39:56,157 - main - ERROR - Unhandled exception: asyncio.run() cannot be called from a running event loop
2025-01-08 00:39:56,488 - main - ERROR - Unhandled exception: asyncio.run() cannot be called from a running event loop
2025-01-08 00:39:56,493 - main - ERROR - Unhandled exception: asyncio.run() cannot be called from a running event loop
2025-01-08 00:39:56,518 - main - ERROR - Unhandled exception: asyncio.run() cannot be called from a running event loop
2025-01-08 00:39:56,523 - main - ERROR - Unhandled exception: asyncio.run() cannot be called from a running event loop
2025-01-08 00:39:56,549 - main - ERROR - Unhandled exception: asyncio.run() cannot be called from a running event loop
2025-01-08 00:39:56,555 - main - ERROR - Unhandled exception: asyncio.run() cannot be called from a running event loop
2025-01-08 00:39:56,813 - main - ERROR - Unhandled exception: asyncio.run() cannot be called from a running event loop
2025-01-08 00:39:56,820 - main - ERROR - Unhandled exception: asyncio.run() cannot be called from a running event loop
2025-01-08 00:39:56,843 - main - ERROR - Unhandled exception: asyncio.run() cannot be called from a running event loop
2025-01-08 00:39:56,850 - main - ERROR - Unhandled exception: asyncio.run() cannot be called from a running event loop
2025-01-08 00:39:56,875 - main - ERROR - Unhandled exception: asyncio.run() cannot be called from a running event loop
2025-01-08 00:39:56,882 - main - ERROR - Unhandled exception: asyncio.run() cannot be called from a running event loop
2025-01-08 00:39:57,139 - main - ERROR - Unhandled exception: asyncio.run() cannot be called from a running event loop
2025-01-08 00:39:57,171 - main - ERROR - Unhandled exception: asyncio.run() cannot be called from a running event loop
2025-01-08 00:39:57,176 - main - ERROR - Unhandled exception: asyncio.run() cannot be called from a running event loop
2025-01-08 00:39:57,244 - main - ERROR - Unhandled exception: asyncio.run() cannot be called from a running event loop
2025-01-08 00:39:57,252 - main - ERROR - Unhandled exception: asyncio.run() cannot be called from a running event loop
2025-01-08 00:39:57,259 - main - ERROR - Unhandled exception: asyncio.run() cannot be called from a running event loop
2025-01-08 00:39:57,450 - main - ERROR - Unhandled exception: asyncio.run() cannot be called from a running event loop
2025-01-08 00:39:57,498 - main - ERROR - Unhandled exception: asyncio.run() cannot be called from a running event loop
2025-01-08 00:39:57,504 - main - ERROR - Unhandled exception: asyncio.run() cannot be called from a running event loop
2025-01-08 00:39:57,575 - main - ERROR - Unhandled exception: asyncio.run() cannot be called from a running event loop
2025-01-08 00:39:57,581 - main - ERROR - Unhandled exception: asyncio.run() cannot be called from a running event loop
2025-01-08 00:39:57,587 - main - ERROR - Unhandled exception: asyncio.run() cannot be called from a running event loop
2025-01-08 00:39:57,760 - main - ERROR - Unhandled exception: asyncio.run() cannot be called from a running event loop
2025-01-08 00:39:57,823 - main - ERROR - Unhandled exception: asyncio.run() cannot be called from a running event loop
2025-01-08 00:39:57,828 - main - ERROR - Unhandled exception: asyncio.run() cannot be called from a running event loop
2025-01-08 00:39:57,900 - main - ERROR - Unhandled exception: asyncio.run() cannot be called from a running event loop
2025-01-08 00:39:57,907 - main - ERROR - Unhandled exception: asyncio.run() cannot be called from a running event loop
2025-01-08 00:39:57,912 - main - ERROR - Unhandled exception: asyncio.run() cannot be called from a running event loop
2025-01-08 00:39:58,071 - main - ERROR - Unhandled exception: asyncio.run() cannot be called from a running event loop
2025-01-08 00:39:58,148 - main - ERROR - Unhandled exception: asyncio.run() cannot be called from a running event loop
2025-01-08 00:39:58,154 - main - ERROR - Unhandled exception: asyncio.run() cannot be called from a running event loop
2025-01-08 00:39:58,226 - main - ERROR - Unhandled exception: asyncio.run() cannot be called from a running event loop
2025-01-08 00:39:58,231 - main - ERROR - Unhandled exception: asyncio.run() cannot be called from a running event loop
2025-01-08 00:39:58,238 - main - ERROR - Unhandled exception: asyncio.run() cannot be called from a running event loop
2025-01-08 00:39:58,381 - main - ERROR - Unhandled exception: asyncio.run() cannot be called from a running event loop
2025-01-08 00:39:58,474 - main - ERROR - Unhandled exception: asyncio.run() cannot be called from a running event loop
2025-01-08 00:39:58,480 - main - ERROR - Unhandled exception: asyncio.run() cannot be called from a running event loop
2025-01-08 00:39:58,553 - main - ERROR - Unhandled exception: asyncio.run() cannot be called from a running event loop
2025-01-08 00:39:58,559 - main - ERROR - Unhandled exception: asyncio.run() cannot be called from a running event loop
2025-01-08 00:39:58,565 - main - ERROR - Unhandled exception: asyncio.run() cannot be called from a running event loop
2025-01-08 01:06:22,687 - main - ERROR - Unhandled exception: asyncio.run() cannot be called from a running event loop
2025-01-08 01:06:22,694 - main - ERROR - Unhandled exception: asyncio.run() cannot be called from a running event loop
2025-01-08 01:06:22,728 - main - ERROR - Unhandled exception: asyncio.run() cannot be called from a running event loop
2025-01-08 01:06:22,734 - main - ERROR - Unhandled exception: asyncio.run() cannot be called from a running event loop
2025-01-08 01:06:22,747 - main - ERROR - Unhandled exception: asyncio.run() cannot be called from a running event loop
2025-01-08 01:06:22,753 - main - ERROR - Unhandled exception: asyncio.run() cannot be called from a running event loop
2025-01-08 01:06:23,011 - main - ERROR - Unhandled exception: asyncio.run() cannot be called from a running event loop
2025-01-08 01:06:23,017 - main - ERROR - Unhandled exception: asyncio.run() cannot be called from a running event loop
2025-01-08 01:06:23,041 - main - ERROR - Unhandled exception: asyncio.run() cannot be called from a running event loop
2025-01-08 01:06:23,048 - main - ERROR - Unhandled exception: asyncio.run() cannot be called from a running event loop
2025-01-08 01:06:23,072 - main - ERROR - Unhandled exception: asyncio.run() cannot be called from a running event loop
2025-01-08 01:06:23,080 - main - ERROR - Unhandled exception: asyncio.run() cannot be called from a running event loop
2025-01-08 01:06:23,335 - main - ERROR - Unhandled exception: asyncio.run() cannot be called from a running event loop
2025-01-08 01:06:23,342 - main - ERROR - Unhandled exception: asyncio.run() cannot be called from a running event loop
2025-01-08 01:06:23,368 - main - ERROR - Unhandled exception: asyncio.run() cannot be called from a running event loop
2025-01-08 01:06:23,373 - main - ERROR - Unhandled exception: asyncio.run() cannot be called from a running event loop
2025-01-08 01:06:23,399 - main - ERROR - Unhandled exception: asyncio.run() cannot be called from a running event loop
2025-01-08 01:06:23,405 - main - ERROR - Unhandled exception: asyncio.run() cannot be called from a running event loop
2025-01-08 01:06:23,665 - main - ERROR - Unhandled exception: asyncio.run() cannot be called from a running event loop
2025-01-08 01:06:23,671 - main - ERROR - Unhandled exception: asyncio.run() cannot be called from a running event loop
2025-01-08 01:06:23,695 - main - ERROR - Unhandled exception: asyncio.run() cannot be called from a running event loop
2025-01-08 01:06:23,701 - main - ERROR - Unhandled exception: asyncio.run() cannot be called from a running event loop
2025-01-08 01:06:23,726 - main - ERROR - Unhandled exception: asyncio.run() cannot be called from a running event loop
2025-01-08 01:06:23,734 - main - ERROR - Unhandled exception: asyncio.run() cannot be called from a running event loop
2025-01-08 01:06:23,991 - main - ERROR - Unhandled exception: asyncio.run() cannot be called from a running event loop
2025-01-08 01:06:23,997 - main - ERROR - Unhandled exception: asyncio.run() cannot be called from a running event loop
2025-01-08 01:06:24,022 - main - ERROR - Unhandled exception: asyncio.run() cannot be called from a running event loop
2025-01-08 01:06:24,028 - main - ERROR - Unhandled exception: asyncio.run() cannot be called from a running event loop
2025-01-08 01:06:24,054 - main - ERROR - Unhandled exception: asyncio.run() cannot be called from a running event loop
2025-01-08 01:06:24,059 - main - ERROR - Unhandled exception: asyncio.run() cannot be called from a running event loop
2025-01-08 01:06:24,317 - main - ERROR - Unhandled exception: asyncio.run() cannot be called from a running event loop
2025-01-08 01:06:24,323 - main - ERROR - Unhandled exception: asyncio.run() cannot be called from a running event loop
2025-01-08 01:06:24,349 - main - ERROR - Unhandled exception: asyncio.run() cannot be called from a running event loop
2025-01-08 01:06:24,354 - main - ERROR - Unhandled exception: asyncio.run() cannot be called from a running event loop
2025-01-08 01:06:24,380 - main - ERROR - Unhandled exception: asyncio.run() cannot be called from a running event loop
2025-01-08 01:06:24,385 - main - ERROR - Unhandled exception: asyncio.run() cannot be called from a running event loop
2025-01-08 01:06:24,641 - main - ERROR - Unhandled exception: asyncio.run() cannot be called from a running event loop
2025-01-08 01:06:24,648 - main - ERROR - Unhandled exception: asyncio.run() cannot be called from a running event loop
2025-01-08 01:06:24,673 - main - ERROR - Unhandled exception: asyncio.run() cannot be called from a running event loop
2025-01-08 01:06:24,679 - main - ERROR - Unhandled exception: asyncio.run() cannot be called from a running event loop
2025-01-08 01:06:24,704 - main - ERROR - Unhandled exception: asyncio.run() cannot be called from a running event loop
2025-01-08 01:06:24,711 - main - ERROR - Unhandled exception: asyncio.run() cannot be called from a running event loop
2025-01-08 01:06:24,969 - main - ERROR - Unhandled exception: asyncio.run() cannot be called from a running event loop
2025-01-08 01:06:24,974 - main - ERROR - Unhandled exception: asyncio.run() cannot be called from a running event loop
2025-01-08 01:06:24,999 - main - ERROR - Unhandled exception: asyncio.run() cannot be called from a running event loop
2025-01-08 01:06:25,005 - main - ERROR - Unhandled exception: asyncio.run() cannot be called from a running event loop
2025-01-08 01:06:25,031 - main - ERROR - Unhandled exception: asyncio.run() cannot be called from a running event loop
2025-01-08 01:06:25,036 - main - ERROR - Unhandled exception: asyncio.run() cannot be called from a running event loop
2025-01-08 01:06:25,294 - main - ERROR - Unhandled exception: asyncio.run() cannot be called from a running event loop
2025-01-08 01:06:25,300 - main - ERROR - Unhandled exception: asyncio.run() cannot be called from a running event loop
2025-01-08 01:06:25,324 - main - ERROR - Unhandled exception: asyncio.run() cannot be called from a running event loop
2025-01-08 01:06:25,331 - main - ERROR - Unhandled exception: asyncio.run() cannot be called from a running event loop
2025-01-08 01:06:25,356 - main - ERROR - Unhandled exception: asyncio.run() cannot be called from a running event loop
2025-01-08 01:06:25,363 - main - ERROR - Unhandled exception: asyncio.run() cannot be called from a running event loop
2025-01-08 01:06:25,618 - main - ERROR - Unhandled exception: asyncio.run() cannot be called from a running event loop
2025-01-08 01:06:25,623 - main - ERROR - Unhandled exception: asyncio.run() cannot be called from a running event loop
2025-01-08 01:06:25,650 - main - ERROR - Unhandled exception: asyncio.run() cannot be called from a running event loop
2025-01-08 01:06:25,655 - main - ERROR - Unhandled exception: asyncio.run() cannot be called from a running event loop
2025-01-08 01:06:25,681 - main - ERROR - Unhandled exception: asyncio.run() cannot be called from a running event loop
2025-01-08 01:06:25,687 - main - ERROR - Unhandled exception: asyncio.run() cannot be called from a running event loop
2025-01-08 01:06:28,324 - main - ERROR - Unhandled exception: asyncio.run() cannot be called from a running event loop
2025-01-08 01:06:28,332 - main - ERROR - Unhandled exception: asyncio.run() cannot be called from a running event loop
2025-01-08 01:06:28,360 - main - ERROR - Unhandled exception: asyncio.run() cannot be called from a running event loop
2025-01-08 01:06:28,676 - main - ERROR - Unhandled exception: asyncio.run() cannot be called from a running event loop
2025-01-08 01:06:28,691 - main - ERROR - Unhandled exception: asyncio.run() cannot be called from a running event loop
2025-01-08 01:06:28,700 - main - ERROR - Unhandled exception: asyncio.run() cannot be called from a running event loop
2025-01-08 01:06:28,722 - main - ERROR - Unhandled exception: asyncio.run() cannot be called from a running event loop
2025-01-08 01:06:28,729 - main - ERROR - Unhandled exception: asyncio.run() cannot be called from a running event loop
2025-01-08 01:06:28,753 - main - ERROR - Unhandled exception: asyncio.run() cannot be called from a running event loop
2025-01-08 01:06:28,987 - main - ERROR - Unhandled exception: asyncio.run() cannot be called from a running event loop
2025-01-08 01:06:29,018 - main - ERROR - Unhandled exception: asyncio.run() cannot be called from a running event loop
2025-01-08 01:06:29,023 - main - ERROR - Unhandled exception: asyncio.run() cannot be called from a running event loop
2025-01-08 01:06:29,049 - main - ERROR - Unhandled exception: asyncio.run() cannot be called from a running event loop
2025-01-08 01:06:29,055 - main - ERROR - Unhandled exception: asyncio.run() cannot be called from a running event loop
2025-01-08 01:06:29,061 - main - ERROR - Unhandled exception: asyncio.run() cannot be called from a running event loop
2025-01-08 01:06:29,298 - main - ERROR - Unhandled exception: asyncio.run() cannot be called from a running event loop
2025-01-08 01:06:29,346 - main - ERROR - Unhandled exception: asyncio.run() cannot be called from a running event loop
2025-01-08 01:06:29,351 - main - ERROR - Unhandled exception: asyncio.run() cannot be called from a running event loop
2025-01-08 02:06:20,875 - main - ERROR - Unhandled exception: 'voicevox_human' object has no attribute 'save_task'
2025-01-08 02:06:20,883 - main - ERROR - Unhandled exception: 'voicevox_human' object has no attribute 'save_task'
2025-01-08 02:10:02,752 - main - ERROR - Unhandled exception: asyncio.run() cannot be called from a running event loop
2025-01-08 02:10:02,759 - main - ERROR - Unhandled exception: asyncio.run() cannot be called from a running event loop
2025-01-08 02:10:35,431 - main - ERROR - Unhandled exception: asyncio.run() cannot be called from a running event loop
2025-01-08 02:10:35,437 - main - ERROR - Unhandled exception: asyncio.run() cannot be called from a running event loop
2025-01-08 23:04:47,048 - main - ERROR - Unhandled exception: デフォルトが存在しない場合について検討（画像がないなど）
2025-01-08 23:07:20,915 - main - ERROR - Unhandled exception: デフォルトが存在しない場合について検討（画像がないなど）
2025-01-08 23:14:38,591 - main - ERROR - Unhandled exception: デフォルトが存在しない場合について検討（画像がないなど）
2025-01-08 23:16:34,448 - main - ERROR - Unhandled exception: デフォルトが存在しない場合について検討（画像がないなど）
2025-01-08 23:17:31,417 - main - ERROR - Unhandled exception: デフォルトが存在しない場合について検討（画像がないなど）
2025-01-21 23:26:22,896 - main - ERROR - Unhandled exception: HTTPConnectionPool(host='localhost', port=50021): Max retries exceeded with url: /speakers (Caused by NewConnectionError('<urllib3.connection.HTTPConnection object at 0x0000020B6717B610>: Failed to establish a new connection: [WinError 10061] 対象のコンピューターによって拒否されたため、接続できませんでした。'))
2025-01-29 21:07:01,614 - main - ERROR - Validation error: [{'type': 'missing', 'loc': ('body', 'saveID'), 'msg': 'Field required', 'input': {'page_mode': 'App', 'client_id': 'test', 'character_id': '016928b4-8e2b-402d-a0aa-9871ba0b07fa'}}]
2025-01-29 22:46:17,670 - main - ERROR - Validation error: [{'type': 'missing', 'loc': ('body', 'saveID'), 'msg': 'Field required', 'input': {'page_mode': 'App', 'client_id': 'test', 'character_id': 'c2ab482d-9e6b-4398-a1e2-6eff99355110'}}]
2025-02-02 18:36:23,270 - main - ERROR - Unhandled exception: Error serializing to JSON: TypeError: 'mappingproxy' object cannot be converted to 'PyDict'
2025-02-02 18:36:23,289 - main - ERROR - Unhandled exception: Error serializing to JSON: TypeError: 'mappingproxy' object cannot be converted to 'PyDict'
2025-02-02 19:22:34,032 - main - ERROR - Unhandled exception: 'mappingproxy' object cannot be converted to 'PyDict'
2025-02-02 19:22:49,246 - main - ERROR - Unhandled exception: 'mappingproxy' object cannot be converted to 'PyDict'
2025-02-02 19:33:40,533 - main - ERROR - Unhandled exception: Error serializing to JSON: TypeError: 'mappingproxy' object cannot be converted to 'PyDict'
2025-02-02 19:33:40,545 - main - ERROR - Unhandled exception: Error serializing to JSON: TypeError: 'mappingproxy' object cannot be converted to 'PyDict'
2025-02-02 19:33:40,833 - main - ERROR - Unhandled exception: Error serializing to JSON: TypeError: 'mappingproxy' object cannot be converted to 'PyDict'
2025-02-02 19:33:40,842 - main - ERROR - Unhandled exception: Error serializing to JSON: TypeError: 'mappingproxy' object cannot be converted to 'PyDict'
2025-02-02 19:33:41,497 - main - ERROR - Unhandled exception: Error serializing to JSON: TypeError: 'mappingproxy' object cannot be converted to 'PyDict'
2025-02-02 19:33:41,506 - main - ERROR - Unhandled exception: Error serializing to JSON: TypeError: 'mappingproxy' object cannot be converted to 'PyDict'
2025-02-02 19:34:00,463 - main - ERROR - Unhandled exception: 'mappingproxy' object cannot be converted to 'PyDict'
2025-02-02 19:34:11,265 - main - ERROR - Unhandled exception: 'mappingproxy' object cannot be converted to 'PyDict'
2025-02-02 19:52:54,080 - main - ERROR - Unhandled exception: Error serializing to JSON: TypeError: 'mappingproxy' object cannot be converted to 'PyDict'
2025-02-02 19:52:54,095 - main - ERROR - Unhandled exception: Error serializing to JSON: TypeError: 'mappingproxy' object cannot be converted to 'PyDict'
2025-02-02 19:52:56,036 - main - ERROR - Unhandled exception: Error serializing to JSON: TypeError: 'mappingproxy' object cannot be converted to 'PyDict'
2025-02-02 19:52:56,350 - main - ERROR - Unhandled exception: Error serializing to JSON: TypeError: 'mappingproxy' object cannot be converted to 'PyDict'
2025-02-02 19:52:56,360 - main - ERROR - Unhandled exception: Error serializing to JSON: TypeError: 'mappingproxy' object cannot be converted to 'PyDict'
2025-02-02 19:52:56,463 - main - ERROR - Unhandled exception: Error serializing to JSON: TypeError: 'mappingproxy' object cannot be converted to 'PyDict'
2025-02-02 19:52:56,472 - main - ERROR - Unhandled exception: Error serializing to JSON: TypeError: 'mappingproxy' object cannot be converted to 'PyDict'
2025-02-02 19:52:56,678 - main - ERROR - Unhandled exception: Error serializing to JSON: TypeError: 'mappingproxy' object cannot be converted to 'PyDict'
2025-02-02 19:52:56,771 - main - ERROR - Unhandled exception: Error serializing to JSON: TypeError: 'mappingproxy' object cannot be converted to 'PyDict'
2025-02-02 19:52:56,779 - main - ERROR - Unhandled exception: Error serializing to JSON: TypeError: 'mappingproxy' object cannot be converted to 'PyDict'
2025-02-02 19:52:56,800 - main - ERROR - Unhandled exception: Error serializing to JSON: TypeError: 'mappingproxy' object cannot be converted to 'PyDict'
2025-02-02 19:52:56,990 - main - ERROR - Unhandled exception: Error serializing to JSON: TypeError: 'mappingproxy' object cannot be converted to 'PyDict'
2025-02-02 19:52:56,999 - main - ERROR - Unhandled exception: Error serializing to JSON: TypeError: 'mappingproxy' object cannot be converted to 'PyDict'
2025-02-02 19:52:57,101 - main - ERROR - Unhandled exception: Error serializing to JSON: TypeError: 'mappingproxy' object cannot be converted to 'PyDict'
2025-02-02 19:52:57,110 - main - ERROR - Unhandled exception: Error serializing to JSON: TypeError: 'mappingproxy' object cannot be converted to 'PyDict'
2025-02-02 19:52:57,180 - main - ERROR - Unhandled exception: Error serializing to JSON: TypeError: 'mappingproxy' object cannot be converted to 'PyDict'
2025-02-02 19:52:57,252 - main - ERROR - Unhandled exception: Error serializing to JSON: TypeError: 'mappingproxy' object cannot be converted to 'PyDict'
2025-02-02 19:52:57,317 - main - ERROR - Unhandled exception: Error serializing to JSON: TypeError: 'mappingproxy' object cannot be converted to 'PyDict'
2025-02-02 19:52:57,454 - main - ERROR - Unhandled exception: Error serializing to JSON: TypeError: 'mappingproxy' object cannot be converted to 'PyDict'
2025-02-02 19:52:57,462 - main - ERROR - Unhandled exception: Error serializing to JSON: TypeError: 'mappingproxy' object cannot be converted to 'PyDict'
2025-02-05 02:27:34,868 - main - ERROR - Unhandled exception: デフォルトが存在しない場合について検討（画像がないなど）
2025-02-07 14:04:34,974 - main - ERROR - Unhandled exception: HTTPConnectionPool(host='localhost', port=50021): Max retries exceeded with url: /speakers (Caused by NewConnectionError('<urllib3.connection.HTTPConnection object at 0x00000211006B0310>: Failed to establish a new connection: [WinError 10061] 対象のコンピューターによって拒否されたため、接続できませんでした。'))
2025-02-07 16:21:50,741 - main - ERROR - Validation error: [{'type': 'missing', 'loc': ('body', 'characterModeState', 'save_id'), 'msg': 'Field required', 'input': {'id': '5de59501-e168-49a3-b8af-0caa106dbfd4', 'tts_software': 'VoiceVox', 'character_name': {'name': 'ずんだもん'}, 'human_image': {'folder_name': 'しろまる式メスガキずんだもん_4'}, 'voice_mode': {'mode': 'ノーマル', 'id': 3, 'id_str': None}, 'voice_state': {'scale': 1}, 'front_name': 'ずんだもん'}}]
2025-02-07 16:21:55,734 - main - ERROR - Validation error: [{'type': 'missing', 'loc': ('body', 'characterModeState', 'save_id'), 'msg': 'Field required', 'input': {'id': '5de59501-e168-49a3-b8af-0caa106dbfd4', 'tts_software': 'VoiceVox', 'character_name': {'name': 'ずんだもん'}, 'human_image': {'folder_name': 'しろまる式メスガキずんだもん_4'}, 'voice_mode': {'mode': 'ノーマル', 'id': 3, 'id_str': None}, 'voice_state': {'scale': 1}, 'front_name': 'ずんだもん'}}]
2025-02-07 16:21:58,892 - main - ERROR - Validation error: [{'type': 'missing', 'loc': ('body', 'characterModeState', 'save_id'), 'msg': 'Field required', 'input': {'id': '5de59501-e168-49a3-b8af-0caa106dbfd4', 'tts_software': 'VoiceVox', 'character_name': {'name': 'ずんだもん'}, 'human_image': {'folder_name': 'しろまる式メスガキずんだもん_4'}, 'voice_mode': {'mode': 'ヘロヘロ', 'id': 75, 'id_str': None}, 'voice_state': {'scale': 1}, 'front_name': 'ずんだもん'}}]
2025-02-07 16:22:37,757 - main - ERROR - Validation error: [{'type': 'missing', 'loc': ('body', 'characterModeState', 'save_id'), 'msg': 'Field required', 'input': {'id': '0ba0a3c2-c8b6-4314-b17e-a81ef84deea0', 'tts_software': 'VoiceVox', 'character_name': {'name': 'ずんだもん'}, 'human_image': {'folder_name': 'しろまる式メスガキずんだもん_4'}, 'voice_mode': {'mode': 'ヘロヘロ', 'id': 75, 'id_str': None}, 'voice_state': {'scale': 1}, 'front_name': 'ずんだもん'}}]
2025-02-07 21:29:35,282 - main - ERROR - Unhandled exception: File at path C:\Users\pokr301qup\python_dev\VoiroStudio\RefucteringVoiroStudio\app\test is not a file.
2025-02-07 21:29:37,527 - main - ERROR - Unhandled exception: File at path C:\Users\pokr301qup\python_dev\VoiroStudio\RefucteringVoiroStudio\app\test is not a file.
2025-02-17 02:54:11,495 - main - ERROR - Unhandled exception: 2 validation errors for AppSettingsModel
セリフ設定.AIによる文章変換の一括設定
  Input should be '無効' or 'ChatGPT' [type=enum, input_value=True, input_type=bool]
    For further information visit https://errors.pydantic.dev/2.8/v/enum
セリフ設定.読み上げ間隔の一括設定
  Input should be less than or equal to 2 [type=less_than_equal, input_value=45, input_type=int]
    For further information visit https://errors.pydantic.dev/2.8/v/less_than_equal
2025-02-17 02:54:16,071 - main - ERROR - Unhandled exception: 2 validation errors for AppSettingsModel
セリフ設定.AIによる文章変換の一括設定
  Input should be '無効' or 'ChatGPT' [type=enum, input_value=True, input_type=bool]
    For further information visit https://errors.pydantic.dev/2.8/v/enum
セリフ設定.読み上げ間隔の一括設定
  Input should be less than or equal to 2 [type=less_than_equal, input_value=45, input_type=int]
    For further information visit https://errors.pydantic.dev/2.8/v/less_than_equal
2025-02-17 02:55:03,341 - main - ERROR - Unhandled exception: 1 validation error for AppSettingsModel
セリフ設定.AIによる文章変換の一括設定
  Input should be '無効' or 'ChatGPT' [type=enum, input_value=True, input_type=bool]
    For further information visit https://errors.pydantic.dev/2.8/v/enum
2025-02-17 02:55:13,919 - main - ERROR - Unhandled exception: 1 validation error for AppSettingsModel
セリフ設定.AIによる文章変換の一括設定
  Input should be '無効' or 'ChatGPT' [type=enum, input_value=True, input_type=bool]
    For further information visit https://errors.pydantic.dev/2.8/v/enum
2025-02-17 02:55:27,110 - main - ERROR - Unhandled exception: 1 validation error for AppSettingsModel
セリフ設定.AIによる文章変換の一括設定
  Input should be '無効' or 'ChatGPT' [type=enum, input_value=True, input_type=bool]
    For further information visit https://errors.pydantic.dev/2.8/v/enum
2025-02-22 22:58:27,707 - main - ERROR - Validation error: [{'type': 'missing', 'loc': ('body', 'characterName'), 'msg': 'Field required', 'input': {'page_mode': 'Chat', 'client_id': 'd42fbc07-cbe2-40e0-be05-597019ea309a', 'character_id': '84887b64-30db-4bae-9a44-31de01566177'}}]
2025-02-22 23:08:42,537 - main - ERROR - Validation error: [{'type': 'missing', 'loc': ('body', 'characterName'), 'msg': 'Field required', 'input': {'page_mode': 'Chat', 'client_id': 'd61b16ef-01e8-4dba-af92-a334f1b8db86', 'character_id': '31984894-6151-4eb8-b735-c8f4e0722905'}}]
2025-02-22 23:14:28,685 - main - ERROR - Validation error: [{'type': 'missing', 'loc': ('body', 'characterName'), 'msg': 'Field required', 'input': {'page_mode': 'Chat', 'client_id': '93600748-fd41-4125-aed9-2b171ed5d21a', 'character_id': '3261c52d-38e3-4948-9360-e46e54553ca5'}}]
2025-02-22 23:22:42,109 - main - ERROR - Validation error: [{'type': 'missing', 'loc': ('body', 'characterName'), 'msg': 'Field required', 'input': {'page_mode': 'Chat', 'client_id': 'bdbce356-7561-4f80-8577-31bb29425c40', 'character_id': '75681bad-5da4-4652-8da4-dab5f26baf6c'}}]
2025-02-22 23:23:07,979 - main - ERROR - Validation error: [{'type': 'missing', 'loc': ('body', 'characterName'), 'msg': 'Field required', 'input': {'page_mode': 'Chat', 'client_id': 'f23cd017-94f4-44d5-a73a-d6d6a270f4ce', 'character_id': '62f85330-f158-4ab6-bb82-f724feeee5b2'}}]
2025-02-23 02:13:35,771 - main - ERROR - Unhandled exception: HTTPConnectionPool(host='localhost', port=50021): Max retries exceeded with url: /speakers (Caused by NewConnectionError('<urllib3.connection.HTTPConnection object at 0x00000225FE03DE90>: Failed to establish a new connection: [WinError 10061] 対象のコンピューターによって拒否されたため、接続できませんでした。'))
2025-02-23 22:15:08,849 - main - ERROR - Unhandled exception: [Errno 2] No such file or directory: 'C:\\Users\\pokr301qup\\python_dev\\VoiroStudio\\RefucteringVoiroStudio\\api\\CharSettingJson\\AIVOICEKnownNames.json'
